<?xml version="1.0" encoding="utf-8"?>
<!-- This URDF was automatically created by SolidWorks to URDF Exporter! Originally created by Stephen Brawner (brawner@gmail.com) 
     Commit Version: 1.6.0-1-g15f4949  Build Version: 1.6.7594.29634
     For more information, please see http://wiki.ros.org/sw_urdf_exporter -->
<robot name="libro_model"
  xmlns:xacro="http://ros.org/wiki/xacro">

  <link name="base_footprint" />
  <joint name="base_footprint_joint" type="fixed">
    <origin xyz="0 0 0.055" rpy="0.0 0.0 0.0"/>
    <parent link="base_footprint" />
    <child link="base_link" />
  </joint>

  <link name="base_link"/>
  <joint name="base_joint" type="fixed">
    <origin xyz="0.0 0.0 0.0" rpy="0.0 0.0 0.0"/>
    <parent link="base_link"/>
    <child link="libro_chassis_link"/>
  </joint>

  <link name="libro_chassis_link">
    <inertial>
      <origin xyz="5.68208583529243E-05 -1.08190137895018E-05 -0.0191328128743083" rpy="0 0 0" />
      <mass value="0.315959634168836" />
      <inertia ixx="0.000237187119369315" ixy="1.02623528819012E-07" ixz="-5.76554239644837E-20" iyy="0.000984715228403803" iyz="3.46081831405105E-20" izz="0.00120943275258583" />
    </inertial>
    <visual>
      <origin xyz="0 0 0" rpy="0 0 0" />
      <geometry>
        <mesh filename="package://libro_model/meshes/base_link.STL" />
      </geometry>
      <material name="">
        <color rgba="1 1 1 1" />
      </material>
    </visual>
    <collision>
      <origin xyz="0 0 0" rpy="0 0 0" />
      <geometry>
        <mesh filename="package://libro_model/meshes/base_link.STL" />
      </geometry>
    </collision>
  </link>
  <link name="right_front_wheel_link">
    <inertial>
      <origin xyz="1.38777878078145E-17 0.000536215321318312 3.46944695195361E-18" rpy="0 0 0" />
      <mass value="0.0420890500835263" />
      <inertia ixx="1.69788467809493E-05" ixy="-1.07143056154772E-22" ixz="3.59209508752315E-22" iyy="2.82266239844783E-05" iyz="2.23488333501653E-21" izz="1.69803313609295E-05" />
    </inertial>
    <visual>
      <origin xyz="0 0 0" rpy="0 0 0" />
      <geometry>
        <mesh filename="package://libro_model/meshes/right_front_wheel_link.STL" />
      </geometry>
      <material name="">
        <color rgba="0.298039215686275 0.298039215686275 0.298039215686275 1" />
      </material>
    </visual>
    <collision>
      <origin xyz="0 0 0" rpy="0 0 0" />
      <geometry>
        <mesh filename="package://libro_model/meshes/right_front_wheel_link.STL" />
      </geometry>
    </collision>
  </link>
  <joint name="right_front_wheel_joint" type="continuous">
    <origin xyz="0.057307 -0.064491 -0.02175" rpy="0 0 0" />
    <parent link="libro_chassis_link" />
    <child link="right_front_wheel_link" />
    <axis xyz="0 1 0" />
    <!-- <limit lower="-180" upper="180" effort="0" velocity="0" /> -->
  </joint>
  <link name="right_rear_wheel_link">
    <inertial>
      <origin xyz="1.38777878078145E-17 0.000536215321318284 6.93889390390723E-18" rpy="0 0 0" />
      <mass value="0.0420890500835264" />
      <inertia ixx="1.69788467809493E-05" ixy="1.57919887602203E-21" ixz="-3.34928854973574E-22" iyy="2.82266239844783E-05" iyz="3.29921671584904E-22" izz="1.69803313609295E-05" />
    </inertial>
    <visual>
      <origin xyz="0 0 0" rpy="0 0 0" />
      <geometry>
        <mesh filename="package://libro_model/meshes/right_rear_wheel_link.STL" />
      </geometry>
      <material name="">
        <color rgba="0.298039215686275 0.298039215686275 0.298039215686275 1" />
      </material>
    </visual>
    <collision>
      <origin xyz="0 0 0" rpy="0 0 0" />
      <geometry>
        <mesh filename="package://libro_model/meshes/right_rear_wheel_link.STL" />
      </geometry>
    </collision>
  </link>
  <joint name="right_rear_wheel_joint" type="continuous">
    <origin xyz="-0.057693 -0.064454 -0.02175" rpy="0 0 0" />
    <parent link="libro_chassis_link" />
    <child link="right_rear_wheel_link" />
    <axis xyz="0 1 0" />
    <!-- <limit lower="-180" upper="180" effort="0" velocity="0" /> -->
  </joint>
  <link name="left_front_wheel_link">
    <inertial>
      <origin xyz="-6.93889390390723E-18 -0.000536215321318298 0" rpy="0 0 0" />
      <mass value="0.0420890500835263" />
      <inertia ixx="1.69788467809493E-05" ixy="1.20055989289706E-21" ixz="-3.34719610585716E-22" iyy="2.82266239844783E-05" iyz="-1.25731607683899E-21" izz="1.69803313609295E-05" />
    </inertial>
    <visual>
      <origin xyz="0 0 0" rpy="0 0 0" />
      <geometry>
        <mesh filename="package://libro_model/meshes/left_front_wheel_link.STL" />
      </geometry>
      <material name="">
        <color rgba="0.298039215686275 0.298039215686275 0.298039215686275 1" />
      </material>
    </visual>
    <collision>
      <origin xyz="0 0 0" rpy="0 0 0" />
      <geometry>
        <mesh filename="package://libro_model/meshes/left_front_wheel_link.STL" />
      </geometry>
    </collision>
  </link>
  <joint name="left_front_wheel_joint" type="continuous">
    <origin xyz="0.057307 0.064455 -0.02175" rpy="0 0 0" />
    <parent link="libro_chassis_link" />
    <child link="left_front_wheel_link" />
    <axis xyz="0 1 0" />
    <!-- <limit lower="-180" upper="180" effort="0" velocity="0" /> -->
  </joint>
  <link name="left_rear_wheel_link">
    <inertial>
      <origin xyz="4.16333634234434E-17 -0.000536215321318353 -3.46944695195361E-16" rpy="0 0 0" />
      <mass value="0.0420890500835263" />
      <inertia ixx="1.69788496293646E-05" ixy="-1.18719665581258E-21" ixz="6.49660441239981E-11" iyy="2.82266239844783E-05" iyz="1.01365580326182E-21" izz="1.69803285125142E-05" />
    </inertial>
    <visual>
      <origin xyz="0 0 0" rpy="0 0 0" />
      <geometry>
        <mesh filename="package://libro_model/meshes/left_rear_wheel_link.STL" />
      </geometry>
      <material name="">
        <color rgba="0.298039215686275 0.298039215686275 0.298039215686275 1" />
      </material>
    </visual>
    <collision>
      <origin xyz="0 0 0" rpy="0 0 0" />
      <geometry>
        <mesh filename="package://libro_model/meshes/left_rear_wheel_link.STL" />
      </geometry>
    </collision>
  </link>
  <joint name="left_rear_wheel_joint" type="continuous">
    <origin xyz="-0.057693 0.064369 -0.02175" rpy="0 0 0" />
    <parent link="libro_chassis_link" />
    <child link="left_rear_wheel_link" />
    <axis xyz="0 1 0" />
    <!-- <limit lower="-180" upper="180" effort="0" velocity="0" /> -->
  </joint>
  <link name="ydlidar_link">
    <inertial>
      <origin xyz="0.0231720323566563 0.00112954738407898 -0.045776403536883" rpy="0 0 0" />
      <mass value="0.0573896608078332" />
      <inertia ixx="1.39246903875836E-05" ixy="9.90784550405998E-07" ixz="-1.12428911988727E-06" iyy="3.45029950880899E-05" iyz="-1.27754764540977E-07" izz="4.72303912642056E-05" />
    </inertial>
    <visual>
      <origin xyz="0 0 0" rpy="0 0 0" />
      <geometry>
        <mesh filename="package://libro_model/meshes/ydlidar_link.STL" />
      </geometry>
      <material name="">
        <color rgba="0.772549019607843 0.752941176470588 0.733333333333333 1" />
      </material>
    </visual>
    <collision>
      <origin xyz="0 0 0" rpy="0 0 0" />
      <geometry>
        <mesh filename="package://libro_model/meshes/ydlidar_link.STL" />
      </geometry>
    </collision>
  </link>
  <joint name="ydlidar_joint" type="fixed">
    <origin xyz="0.056136 -0.00016187 0.0859" rpy="0 0 0" />
    <parent link="libro_chassis_link" />
    <child link="ydlidar_link" />
    <axis xyz="0 0 0" />
  </joint>
  <link name="lidar_underframe_link">
    <inertial>
      <origin xyz="0.0713736461903973 -9.66678635817838E-05 0.01" rpy="0 0 0" />
      <mass value="0.119982831853072" />
      <inertia ixx="3.99842050248324E-05" ixy="8.82530750051684E-21" ixz="-7.14343913461121E-22" iyy="0.000103956889382291" iyz="5.54441914502247E-22" izz="0.000135942238950252" />
    </inertial>
    <visual>
      <origin xyz="0 0 0" rpy="0 0 0" />
      <geometry>
        <mesh filename="package://libro_model/meshes/lidar_underframe_link.STL" />
      </geometry>
      <material name="">
        <color rgba="1 1 1 1" />
      </material>
    </visual>
    <collision>
      <origin xyz="0 0 0" rpy="0 0 0" />
      <geometry>
        <mesh filename="package://libro_model/meshes/lidar_underframe_link.STL" />
      </geometry>
    </collision>
  </link>
  <joint name="lidar_underframe_joint" type="fixed">
    <origin xyz="0 0 0" rpy="0 0 0" />
    <parent link="libro_chassis_link" />
    <child link="lidar_underframe_link" />
    <axis xyz="0 0 0" />
  </joint>

  <link name="camera_link">
    <inertial>
      <origin xyz="-0.00303115254709119 9.98333360424652E-16 -5.12569483805715E-05" rpy="0 0 0" />
      <mass value="0.00145671307075292" />
      <inertia ixx="6.93646665527772E-08" ixy="3.04630454817989E-24" ixz="-1.09673943150479E-10" iyy="3.98881873637141E-08" iyz="-9.33337790838574E-24" izz="3.98920145491929E-08" />
    </inertial>
    <visual>
      <origin xyz="0 0 0" rpy="0 0 0" />
      <geometry>
        <mesh filename="package://libro_model/meshes/camera_link.STL" />
      </geometry>
      <material name="">
        <color rgba="1 1 1 1" />
      </material>
    </visual>
    <collision>
      <origin xyz="0 0 0" rpy="0 0 0" />
      <geometry>
        <mesh filename="package://libro_model/meshes/camera_link.STL" />
      </geometry>
    </collision>
  </link>
  <joint name="camera_joint" type="fixed">
    <origin xyz="0.12531 -0.00043191 -0.023" rpy="0 0 0" />
    <parent link="libro_chassis_link" />
    <child link="camera_link" />
    <axis xyz="0 1 0" />
  </joint>
    <link
    name="imu_link">
    <inertial>
      <origin
        xyz="1.38777878078145E-17 -1.76569405348702E-20 0.000480459453048733"
        rpy="0 0 0" />
      <mass
        value="0.00505378695593601" />
      <inertia
        ixx="1.40522552943832E-07"
        ixy="2.7306391434977E-40"
        ixz="-2.54746894131233E-40"
        iyy="1.40522552943832E-07"
        iyz="-1.06659580591594E-25"
        izz="2.51063192322412E-07" />
    </inertial>
    <visual>
      <origin
        xyz="0 0 0"
        rpy="0 0 0" />
      <geometry>
        <mesh
          filename="package://libro_model/meshes/imu_link.STL" />
      </geometry>
      <material
        name="">
        <color
          rgba="0.898039215686275 0.917647058823529 0.929411764705882 1" />
      </material>
    </visual>
    <collision>
      <origin
        xyz="0 0 0"
        rpy="0 0 0" />
      <geometry>
        <mesh
          filename="package://libro_model/meshes/imu_link.STL" />
      </geometry>
    </collision>
  </link>
  <joint
    name="imu_joint"
    type="fixed">
    <origin
      xyz="0.099307 -1.2058E-05 -0.0305"
      rpy="0 0 0" />
    <parent
      link="libro_chassis_link" />
    <child
      link="imu_link" />
    <axis
      xyz="0 0 1" />
  </joint>
</robot>
